Workbook

Sheet Indice

Sheet Parameters
A1: Individuo | B1: Età
A2: 1 | B2: 68
A3: 2 | B3: 28
A4: 3 | B4: 44
A5: 4 | B5: 63
A6: 5 | B6: 33
A7: 6 | B7: 34
A8: 7 | B8: 51
A9: 8 | B9: 67
A10: 9 | B10: 78
A11: 10 | B11: 55
A12: 11 | B12: 52
A13: 12 | B13: 23
... A251: 250 | B251: 37

Sheet Data
A1: Età generate | B1: Gruppo di appartenenza
A2: =Parameters!B2 -> 68 | B2: 3
A3: =Parameters!B3 -> 28 | B3: 3
A4: =Parameters!B4 -> 44 | B4: 3
A5: =Parameters!B5 -> 63 | B5: 1
A6: =Parameters!B6 -> 33 | B6: 1
A7: =Parameters!B7 -> 34 | B7: 1
A8: =Parameters!B8 -> 51 | B8: 2
A9: =Parameters!B9 -> 67 | B9: 3
A10: =Parameters!B10 -> 78 | B10: 1
A11: =Parameters!B11 -> 55 | B11: 2
A12: =Parameters!B12 -> 52 | B12: 2
A13: =Parameters!B13 -> 23 | B13: 1
... A251: =Parameters!B251 -> 37 | B251: 3

Sheet Sample_filter
A1: Età | B1: Gruppo | AC1: 1
A2: {=_xlfn._xlws.FILTER(Data!A2:B251,Data!B2:B251='Statistical Insight'!A5,"Nessun valore trovato")} -> 51 | B2: 2 | AC2: 2
A3: 55 | B3: 2 | AC3: 3
A4: 52 | B4: 2 | AC4: 4
A5: 24 | B5: 2
A6: 66 | B6: 2
A7: 14 | B7: 2
A8: 62 | B8: 2
A9: 35 | B9: 2
A10: 24 | B10: 2
A11: 33 | B11: 2
A12: 40 | B12: 2
A13: 46 | B13: 2
A14: 50 | B14: 2
A15: 29 | B15: 2
A16: 49 | B16: 2
... A59: 53 | B59: 2

Sheet Sample_if
A1: Età | B1: Gruppo | C1: Sotto-Campione scelto | AA1: 1
A2: =Data!A2 -> 68 | B2: =Data!B2 -> 3 | C2: =IF(B2='Statistical Insight'!$A$5,A2," ") | AA2: 2
A3: =Data!A3 -> 28 | B3: =Data!B3 -> 3 | C3: =IF(B3='Statistical Insight'!$A$5,A3," ") | AA3: 3
A4: =Data!A4 -> 44 | B4: =Data!B4 -> 3 | C4: =IF(B4='Statistical Insight'!$A$5,A4," ") | AA4: 4
A5: =Data!A5 -> 63 | B5: =Data!B5 -> 1 | C5: =IF(B5='Statistical Insight'!$A$5,A5," ")
A6: =Data!A6 -> 33 | B6: =Data!B6 -> 1 | C6: =IF(B6='Statistical Insight'!$A$5,A6," ")
A7: =Data!A7 -> 34 | B7: =Data!B7 -> 1 | C7: =IF(B7='Statistical Insight'!$A$5,A7," ")
A8: =Data!A8 -> 51 | B8: =Data!B8 -> 2 | C8: =IF(B8='Statistical Insight'!$A$5,A8," ") -> 51
A9: =Data!A9 -> 67 | B9: =Data!B9 -> 3 | C9: =IF(B9='Statistical Insight'!$A$5,A9," ")
A10: =Data!A10 -> 78 | B10: =Data!B10 -> 1 | C10: =IF(B10='Statistical Insight'!$A$5,A10," ")
A11: =Data!A11 -> 55 | B11: =Data!B11 -> 2 | C11: =IF(B11='Statistical Insight'!$A$5,A11," ") -> 55
A12: =Data!A12 -> 52 | B12: =Data!B12 -> 2 | C12: =IF(B12='Statistical Insight'!$A$5,A12," ") -> 52
A13: =Data!A13 -> 23 | B13: =Data!B13 -> 1 | C13: =IF(B13='Statistical Insight'!$A$5,A13," ")
A14: =Data!A14 -> 24 | B14: =Data!B14 -> 2 | C14: =IF(B14='Statistical Insight'!$A$5,A14," ") -> 24
A15: =Data!A15 -> 43 | B15: =Data!B15 -> 4 | C15: =IF(B15='Statistical Insight'!$A$5,A15," ")
A16: =Data!A16 -> 70 | B16: =Data!B16 -> 1 | C16: =IF(B16='Statistical Insight'!$A$5,A16," ")
... A251: =Data!A251 -> 37 | B251: =Data!B251 -> 3 | C251: =IF(B251='Statistical Insight'!$A$5,A251," ")

Sheet Statistical Insight
A1: Numerosità Campionaria | B1: Media Popolazione | C1: Media Campionaria | D1: Varianza popolazione | E1: Deviazione Standard popolazione | F1: Errore standard | G1: Gradi di libertà | H1: Confidenza | I1: Alfa | J1: Z | K1: Limite inferiore | L1: Limite superiore | M1: Test Z
A2: =COUNT(Sample_filter!A:A) -> 58 | B2: =AVERAGE(Parameters!B:B) -> 46.92 | C2: =AVERAGE(Sample_filter!A:A) -> 45.034483 | D2: =_xlfn.VAR.P(Parameters!B:B) -> 395.4016 | E2: =SQRT(D2) -> 19.884708 | F2: =E2/SQRT(A2) -> 2.61099 | G2: =A2-1 -> 57 | H2: 0.95 | I2: 0.05 | J2: =_xlfn.NORM.S.INV(1-I2/2) -> 1.959964 | K2: =C2-J2*F2 -> 39.917036 | L2: =C2+J2*F2 -> 50.151929 | M2: =(B2-C2)/F2 -> 0.72214647
A4: Campione Gruppo
A5: 2
B9: {=_xlfn._xlws.FILTER('Annotazioni statistiche'!B1:B4,'Annotazioni statistiche'!A1:A4=A5)} -> Campione 2 La deviazione standard della popolazione è di 19,88, questo indica una moderata dispersione dei dati rispetto alla media. La media campionaria e di 45,03. Rispetto alla media della popolazione (46,92) la differenza è di 1,87 punti, inferiore all'errore standard. L'intervallo di confidenza del 95% della popolazione va da 39,92 al 50,15. Questo conferma che la stima campionaria è affidabile e rappresentativa della popolazione. il test Z restituisce 0,72, inferiore al valore critico di 1,96, il che implica che non è vi è evidenza statistica per rifiutare l'ipotesi nulla. la media del campione non differisce significativamente dalla media della popolazione.

Sheet (Un)correlated Variables
A1: Sample data (età) | B1: Numero gatti | C1: Età partner | D1: Gruppo | F1: Correlazione tra età del campione ed età Partner
A2: 68 | B2: 0 | C2: 67 | D2: 3 | F2: =PEARSON(A2:A67,C2:C67) -> 0.3986229
A3: 28 | B3: 1 | C3: 32 | D3: 3
A4: 44 | B4: 3 | C4: 44 | D4: 3
A5: 67 | B5: 3 | C5: 68 | D5: 3
A6: 33 | B6: 2 | C6: 32 | D6: 3
A7: 40 | B7: 3 | C7: 43 | D7: 3
A8: 71 | B8: 0 | C8: 70 | D8: 3
A9: 60 | B9: 2 | C9: 57 | D9: 3
A10: 64 | B10: 2 | C10: 62 | D10: 3
A11: 42 | B11: 1 | C11: 41 | D11: 3
A12: 53 | B12: 3 | C12: 52 | D12: 3
A13: 46 | B13: 1 | C13: 48 | D13: 3
A14: 60 | B14: 2 | C14: 57 | D14: 3
... A18: 50 | B18: 0 | C18: 47 | D18: 3
A19: 36 | B19: 2 | C19: 36 | D19: 3 | F19: Correlazione tra età del campione e numero gatti posseduti
A20: 31 | B20: 1 | C20: 30 | D20: 3 | F20: =PEARSON(A2:A67,B2:B67) -> -0.25900961
A21: 70 | B21: 3 | C21: 68 | D21: 3
A22: 73 | B22: 0 | C22: 75 | D22: 3
A23: 46 | B23: 2 | C23: 44 | D23: 3
A24: 26 | B24: 1 | C24: 25 | D24: 3
A25: 54 | B25: 3 | C25: 32 | D25: 3
A26: 35 | B26: 3 | C26: 67 | D26: 3
A27: 64 | B27: 0 | C27: 39 | D27: 3
A28: 37 | B28: 2 | C28: 32 | D28: 3
A29: 32 | B29: 2 | C29: 56 | D29: 3
A30: 54 | B30: 2 | C30: 39 | D30: 3
A31: 36 | B31: 3 | C31: 82 | D31: 3
A32: 80 | B32: 0 | C32: 70 | D32: 3
... A36: 60 | B36: 1 | C36: 55 | D36: 3
A37: 32 | B37: 2 | C37: 25 | D37: 3 | F37: Correlazione tra età del partner e numero gatti posseduti
A38: 54 | B38: 3 | C38: 39 | D38: 3 | F38: =PEARSON(C2:C67,B2:B67) -> -0.039614761
A39: 20 | B39: 2 | C39: 61 | D39: 3
A40: 25 | B40: 3 | C40: 65 | D40: 3
A41: 41 | B41: 3 | C41: 26 | D41: 3
A42: 60 | B42: 0 | C42: 60 | D42: 3
A43: 68 | B43: 3 | C43: 81 | D43: 3
A44: 29 | B44: 3 | C44: 46 | D44: 3
A45: 63 | B45: 0 | C45: 59 | D45: 3
A46: 80 | B46: 2 | C46: 61 | D46: 3
...

Sheet Linear Regression
A1: Individuo | B1: Età
A2: 1 | B2: 68
A3: 2 | B3: 28
A4: 3 | B4: 44
A5: 4 | B5: 63
A6: 5 | B6: 33
A7: 6 | B7: 34
A8: 7 | B8: 51
A9: 8 | B9: 67
A10: 9 | B10: 78
A11: 10 | B11: 55
A12: 11 | B12: 52
A13: 12 | B13: 23
... A17: 16 | B17: 66
A18: 17 | B18: 56 | E18: Rank | F18: Età
A19: 18 | B19: 23 | E19: =A161 -> 160 | F19: =B161 -> 55
A20: 19 | B20: 58
A21: 20 | B21: 14
A22: 21 | B22: 62
A23: 22 | B23: 70
A24: 23 | B24: 35
A25: 24 | B25: 33
A26: 25 | B26: 40
A27: 26 | B27: 71
A28: 27 | B28: 73
A29: 28 | B29: 60
A30: 29 | B30: 49
A31: 30 | B31: 64
... A251: 250 | B251: 37

Sheet Note di utilizzo
A1: Sezione | B1: Problema/Attività | C1: Azione/Soluzione | D1: Commento
A2: Parameters | B2: Creazione 250 età variabili | C2: Generazione età random basata su distribuzione normale | D2: Ho utilizzato media =46 e dev.std=20 con limiti 1-100 per evitare valori fuori scala.
A3: Data | B3: Assegnazione gruppo agli individui creati | C3: Assegnazione casuale gruppo 1-4 | D3: Utilizzata funizone =casuale.tra(1;4)
A4: Sample | B4: Isolare un gruppo alla volta | C4: Ho utilizzato due approcci: funzione Filtro dinamico e funzione Se | D4: Ho cercato di seguire il più possibile la consegna, ma ho ritenuto che per evidenziare meglio un gruppo singolo l'opzione della funizione se fosse più "funzionale", così ho deciso di creare due tab alternativi. Per la scelta del gruppo nel sample_if ho utilizzato la convalida dati. Il foglio sample_filter è invece collegato al campo convalida del tab Statistical Insight
A5: Statistical Insight | B5: Analisi satistica per gruppo (selezionabile) | C5: Tabelle calcolate dinamicamente via convalida dati | D5: Cambiando il gruppo nella convalida tutti i calcoli /statistiche e i commenti si aggiornano automaticamente
A6: (Un)correlated Variables | B6: Variabili derivate: età partner e numero gatti | C6: Età partner = età + random (-5 o +5) se età maggiore di 18. Gatti random tra 0 e 3. | D6: Ho rimosso dal gruppo gli individui minorenni
A7: Linear regression | B7: Scatter plot con regressione lineare | C7: Scatter + linea di tendenza (equazione e R2 visibili) ed evidenziato individuo 160 | D7: Ho deciso di usare il gruppo 3 come campione perché più numeroso.

Sheet Annotazioni statistiche
A1: 1 | B1: Campione 1 La deviazione standard della popolazione è di 19,88, questo indica una moderata dispersione dei dati rispetto alla media. La media campionaria è di 45,59. Rispetto alla media della popolazione (46,92) la differenza è di 1,33 punti, inferiore all'errore standard. L'intervallo di confidenza del 95% della popolazione va da 40, 38 al 50,80. Questo conferma che la stima campionaria è affidabile e rappresentativa della popolazione. il test Z restituisce 0,50, inferiore al valore critico di 1,96, il che implica che non è vi è evidenza statistica per rifiutare l'ipotesi nulla. la media del campione non differisce significativamente dalla media della popolazione.
A2: 2 | B2: Campione 2 La deviazione standard della popolazione è di 19,88, questo indica una moderata dispersione dei dati rispetto alla media. La media campionaria e di 45,03. Rispetto alla media della popolazione (46,92) la differenza è di 1,87 punti, inferiore all'errore standard. L'intervallo di confidenza del 95% della popolazione va da 39,92 al 50,15. Questo conferma che la stima campionaria è affidabile e rappresentativa della popolazione. il test Z restituisce 0,72, inferiore al valore critico di 1,96, il che implica che non è vi è evidenza statistica per rifiutare l'ipotesi nulla. la media del campione non differisce significativamente dalla media della popolazione.
A3: 3 | B3: Campione 3 La deviazione standard della popolazione è di 19,88, questo indica una moderata dispersione dei dati rispetto alla media. La media campionaria è di 47,30. Rispetto alla media della popolazione (46,92) la differenza è di 0,38 punti, molto ridotta rispetto all'errore standard. L'intervallo di confidenza del 95% della popolazione va da 42,61 al 52,00. Questo conferma che la stima campionaria è affidabile e rappresentativa della popolazione. il test Z restituisce -0,16, inferiore al valore critico di 1,96, il che implica che non è vi è evidenza statistica per rifiutare l'ipotesi nulla. la media del campione non differisce significativamente dalla media della popolazione.
A4: 4 | B4: Campione 4 La deviazione standard della popolazione è di 19,88, questo indica una moderata dispersione dei dati rispetto alla media. La media campionaria è di 49,27. Rispetto alla media della popolazione (46,92) la differenza è di 2,38 punti, vicino all'errore standard tuttavia ancora inferiore. L'intervallo di confidenza del 95% della popolazione va da 44,51 al 54,03. Questo conferma che la stima campionaria è affidabile e rappresentativa della popolazione. il test Z restituisce -0,97, inferiore al valore critico di 1,96, il che implica che non è vi è evidenza statistica per rifiutare l'ipotesi nulla. la media del campione non differisce significativamente dalla media della popolazione.
